{
 "cells": [
  {
   "cell_type": "code",
   "execution_count": 1,
   "id": "4ebdaba3",
   "metadata": {},
   "outputs": [],
   "source": [
    "# pip/conda install keras\n",
    "# pip install tensorflow"
   ]
  },
  {
   "cell_type": "code",
   "execution_count": 2,
   "id": "d2f2bd4b",
   "metadata": {},
   "outputs": [
    {
     "name": "stderr",
     "output_type": "stream",
     "text": [
      "2024-02-12 18:51:12.870705: I external/local_tsl/tsl/cuda/cudart_stub.cc:31] Could not find cuda drivers on your machine, GPU will not be used.\n",
      "2024-02-12 18:51:13.200918: E external/local_xla/xla/stream_executor/cuda/cuda_dnn.cc:9261] Unable to register cuDNN factory: Attempting to register factory for plugin cuDNN when one has already been registered\n",
      "2024-02-12 18:51:13.201034: E external/local_xla/xla/stream_executor/cuda/cuda_fft.cc:607] Unable to register cuFFT factory: Attempting to register factory for plugin cuFFT when one has already been registered\n",
      "2024-02-12 18:51:13.244737: E external/local_xla/xla/stream_executor/cuda/cuda_blas.cc:1515] Unable to register cuBLAS factory: Attempting to register factory for plugin cuBLAS when one has already been registered\n",
      "2024-02-12 18:51:13.377055: I external/local_tsl/tsl/cuda/cudart_stub.cc:31] Could not find cuda drivers on your machine, GPU will not be used.\n",
      "2024-02-12 18:51:13.380279: I tensorflow/core/platform/cpu_feature_guard.cc:182] This TensorFlow binary is optimized to use available CPU instructions in performance-critical operations.\n",
      "To enable the following instructions: AVX2 FMA, in other operations, rebuild TensorFlow with the appropriate compiler flags.\n",
      "2024-02-12 18:51:15.471753: W tensorflow/compiler/tf2tensorrt/utils/py_utils.cc:38] TF-TRT Warning: Could not find TensorRT\n",
      "/home/mattmori/anaconda3/lib/python3.9/site-packages/scipy/__init__.py:146: UserWarning: A NumPy version >=1.16.5 and <1.23.0 is required for this version of SciPy (detected version 1.26.3\n",
      "  warnings.warn(f\"A NumPy version >={np_minversion} and <{np_maxversion}\"\n"
     ]
    }
   ],
   "source": [
    "from keras.preprocessing.image import ImageDataGenerator"
   ]
  },
  {
   "cell_type": "code",
   "execution_count": 3,
   "id": "2eb2b24c",
   "metadata": {},
   "outputs": [],
   "source": [
    "train_directory = 'pet_images/'"
   ]
  },
  {
   "cell_type": "code",
   "execution_count": 4,
   "id": "3227467a",
   "metadata": {},
   "outputs": [
    {
     "name": "stdout",
     "output_type": "stream",
     "text": [
      "Found 1660 images belonging to 5 classes.\n"
     ]
    }
   ],
   "source": [
    "train_datagen = ImageDataGenerator(rescale=1/255,                   \n",
    "                                   validation_split=0.2)\n",
    "\n",
    "train_generator = train_datagen.flow_from_directory(\n",
    "train_directory, \n",
    "target_size=(256,256), \n",
    "color_mode='rgb', \n",
    "batch_size=64, \n",
    "class_mode='categorical', \n",
    "subset='training',\n",
    "shuffle=True,\n",
    "seed=42\n",
    ")\n"
   ]
  },
  {
   "cell_type": "code",
   "execution_count": 5,
   "id": "14fa4a91",
   "metadata": {},
   "outputs": [
    {
     "name": "stdout",
     "output_type": "stream",
     "text": [
      "Found 414 images belonging to 5 classes.\n"
     ]
    }
   ],
   "source": [
    "validation_generator = train_datagen.flow_from_directory(\n",
    "train_directory,\n",
    "target_size=(256,256), \n",
    "color_mode='rgb', \n",
    "batch_size=64, \n",
    "class_mode='categorical', \n",
    "subset='validation', \n",
    "shuffle=False\n",
    ")"
   ]
  },
  {
   "cell_type": "code",
   "execution_count": 21,
   "id": "482e9cb8",
   "metadata": {},
   "outputs": [
    {
     "name": "stderr",
     "output_type": "stream",
     "text": [
      "2024-02-12 18:58:19.970661: W external/local_tsl/tsl/framework/cpu_allocator_impl.cc:83] Allocation of 4228120576 exceeds 10% of free system memory.\n",
      "2024-02-12 18:58:22.731706: W external/local_tsl/tsl/framework/cpu_allocator_impl.cc:83] Allocation of 1057030144 exceeds 10% of free system memory.\n"
     ]
    },
    {
     "ename": "InvalidArgumentError",
     "evalue": "Graph execution error:\n\nDetected at node categorical_crossentropy/softmax_cross_entropy_with_logits defined at (most recent call last):\n  File \"/home/mattmori/anaconda3/lib/python3.9/runpy.py\", line 197, in _run_module_as_main\n\n  File \"/home/mattmori/anaconda3/lib/python3.9/runpy.py\", line 87, in _run_code\n\n  File \"/home/mattmori/anaconda3/lib/python3.9/site-packages/ipykernel_launcher.py\", line 16, in <module>\n\n  File \"/home/mattmori/anaconda3/lib/python3.9/site-packages/traitlets/config/application.py\", line 846, in launch_instance\n\n  File \"/home/mattmori/anaconda3/lib/python3.9/site-packages/ipykernel/kernelapp.py\", line 677, in start\n\n  File \"/home/mattmori/anaconda3/lib/python3.9/site-packages/tornado/platform/asyncio.py\", line 199, in start\n\n  File \"/home/mattmori/anaconda3/lib/python3.9/asyncio/base_events.py\", line 601, in run_forever\n\n  File \"/home/mattmori/anaconda3/lib/python3.9/asyncio/base_events.py\", line 1905, in _run_once\n\n  File \"/home/mattmori/anaconda3/lib/python3.9/asyncio/events.py\", line 80, in _run\n\n  File \"/home/mattmori/anaconda3/lib/python3.9/site-packages/ipykernel/kernelbase.py\", line 471, in dispatch_queue\n\n  File \"/home/mattmori/anaconda3/lib/python3.9/site-packages/ipykernel/kernelbase.py\", line 460, in process_one\n\n  File \"/home/mattmori/anaconda3/lib/python3.9/site-packages/ipykernel/kernelbase.py\", line 367, in dispatch_shell\n\n  File \"/home/mattmori/anaconda3/lib/python3.9/site-packages/ipykernel/kernelbase.py\", line 662, in execute_request\n\n  File \"/home/mattmori/anaconda3/lib/python3.9/site-packages/ipykernel/ipkernel.py\", line 360, in do_execute\n\n  File \"/home/mattmori/anaconda3/lib/python3.9/site-packages/ipykernel/zmqshell.py\", line 532, in run_cell\n\n  File \"/home/mattmori/anaconda3/lib/python3.9/site-packages/IPython/core/interactiveshell.py\", line 2863, in run_cell\n\n  File \"/home/mattmori/anaconda3/lib/python3.9/site-packages/IPython/core/interactiveshell.py\", line 2909, in _run_cell\n\n  File \"/home/mattmori/anaconda3/lib/python3.9/site-packages/IPython/core/async_helpers.py\", line 129, in _pseudo_sync_runner\n\n  File \"/home/mattmori/anaconda3/lib/python3.9/site-packages/IPython/core/interactiveshell.py\", line 3106, in run_cell_async\n\n  File \"/home/mattmori/anaconda3/lib/python3.9/site-packages/IPython/core/interactiveshell.py\", line 3309, in run_ast_nodes\n\n  File \"/home/mattmori/anaconda3/lib/python3.9/site-packages/IPython/core/interactiveshell.py\", line 3369, in run_code\n\n  File \"/tmp/ipykernel_14199/1985418639.py\", line 21, in <cell line: 21>\n\n  File \"/home/mattmori/anaconda3/lib/python3.9/site-packages/keras/src/utils/traceback_utils.py\", line 65, in error_handler\n\n  File \"/home/mattmori/anaconda3/lib/python3.9/site-packages/keras/src/engine/training.py\", line 1807, in fit\n\n  File \"/home/mattmori/anaconda3/lib/python3.9/site-packages/keras/src/engine/training.py\", line 1401, in train_function\n\n  File \"/home/mattmori/anaconda3/lib/python3.9/site-packages/keras/src/engine/training.py\", line 1384, in step_function\n\n  File \"/home/mattmori/anaconda3/lib/python3.9/site-packages/keras/src/engine/training.py\", line 1373, in run_step\n\n  File \"/home/mattmori/anaconda3/lib/python3.9/site-packages/keras/src/engine/training.py\", line 1151, in train_step\n\n  File \"/home/mattmori/anaconda3/lib/python3.9/site-packages/keras/src/engine/training.py\", line 1209, in compute_loss\n\n  File \"/home/mattmori/anaconda3/lib/python3.9/site-packages/keras/src/engine/compile_utils.py\", line 277, in __call__\n\n  File \"/home/mattmori/anaconda3/lib/python3.9/site-packages/keras/src/losses.py\", line 143, in __call__\n\n  File \"/home/mattmori/anaconda3/lib/python3.9/site-packages/keras/src/losses.py\", line 270, in call\n\n  File \"/home/mattmori/anaconda3/lib/python3.9/site-packages/keras/src/losses.py\", line 2221, in categorical_crossentropy\n\n  File \"/home/mattmori/anaconda3/lib/python3.9/site-packages/keras/src/backend.py\", line 5579, in categorical_crossentropy\n\nlogits and labels must be broadcastable: logits_size=[64,3] labels_size=[64,5]\n\t [[{{node categorical_crossentropy/softmax_cross_entropy_with_logits}}]] [Op:__inference_train_function_2741]",
     "output_type": "error",
     "traceback": [
      "\u001b[0;31m---------------------------------------------------------------------------\u001b[0m",
      "\u001b[0;31mInvalidArgumentError\u001b[0m                      Traceback (most recent call last)",
      "Input \u001b[0;32mIn [21]\u001b[0m, in \u001b[0;36m<cell line: 21>\u001b[0;34m()\u001b[0m\n\u001b[1;32m     17\u001b[0m model\u001b[38;5;241m.\u001b[39madd(Dense(\u001b[38;5;241m3\u001b[39m, activation\u001b[38;5;241m=\u001b[39m\u001b[38;5;124m'\u001b[39m\u001b[38;5;124msoftmax\u001b[39m\u001b[38;5;124m'\u001b[39m))\n\u001b[1;32m     19\u001b[0m model\u001b[38;5;241m.\u001b[39mcompile(loss\u001b[38;5;241m=\u001b[39m\u001b[38;5;124m'\u001b[39m\u001b[38;5;124mcategorical_crossentropy\u001b[39m\u001b[38;5;124m'\u001b[39m,\n\u001b[1;32m     20\u001b[0m               optimizer\u001b[38;5;241m=\u001b[39m\u001b[38;5;124m'\u001b[39m\u001b[38;5;124madam\u001b[39m\u001b[38;5;124m'\u001b[39m,metrics\u001b[38;5;241m=\u001b[39m[\u001b[38;5;124m'\u001b[39m\u001b[38;5;124maccuracy\u001b[39m\u001b[38;5;124m'\u001b[39m])\n\u001b[0;32m---> 21\u001b[0m \u001b[43mmodel\u001b[49m\u001b[38;5;241;43m.\u001b[39;49m\u001b[43mfit\u001b[49m\u001b[43m(\u001b[49m\u001b[43mtrain_generator\u001b[49m\u001b[43m,\u001b[49m\n\u001b[1;32m     22\u001b[0m \u001b[43m          \u001b[49m\u001b[43msteps_per_epoch\u001b[49m\u001b[38;5;241;43m=\u001b[39;49m\u001b[38;5;241;43m40\u001b[39;49m\u001b[43m,\u001b[49m\n\u001b[1;32m     23\u001b[0m \u001b[43m          \u001b[49m\u001b[43mepochs\u001b[49m\u001b[38;5;241;43m=\u001b[39;49m\u001b[38;5;241;43m1\u001b[39;49m\u001b[43m,\u001b[49m\n\u001b[1;32m     24\u001b[0m \u001b[43m          \u001b[49m\u001b[43mvalidation_data\u001b[49m\u001b[38;5;241;43m=\u001b[39;49m\u001b[43m(\u001b[49m\u001b[43mvalidation_generator\u001b[49m\u001b[43m)\u001b[49m\u001b[43m,\u001b[49m\n\u001b[1;32m     25\u001b[0m \u001b[43m          \u001b[49m\u001b[43mvalidation_steps\u001b[49m\u001b[38;5;241;43m=\u001b[39;49m\u001b[38;5;241;43m10\u001b[39;49m\u001b[43m)\u001b[49m\n",
      "File \u001b[0;32m~/anaconda3/lib/python3.9/site-packages/keras/src/utils/traceback_utils.py:70\u001b[0m, in \u001b[0;36mfilter_traceback.<locals>.error_handler\u001b[0;34m(*args, **kwargs)\u001b[0m\n\u001b[1;32m     67\u001b[0m     filtered_tb \u001b[38;5;241m=\u001b[39m _process_traceback_frames(e\u001b[38;5;241m.\u001b[39m__traceback__)\n\u001b[1;32m     68\u001b[0m     \u001b[38;5;66;03m# To get the full stack trace, call:\u001b[39;00m\n\u001b[1;32m     69\u001b[0m     \u001b[38;5;66;03m# `tf.debugging.disable_traceback_filtering()`\u001b[39;00m\n\u001b[0;32m---> 70\u001b[0m     \u001b[38;5;28;01mraise\u001b[39;00m e\u001b[38;5;241m.\u001b[39mwith_traceback(filtered_tb) \u001b[38;5;28;01mfrom\u001b[39;00m \u001b[38;5;28;01mNone\u001b[39;00m\n\u001b[1;32m     71\u001b[0m \u001b[38;5;28;01mfinally\u001b[39;00m:\n\u001b[1;32m     72\u001b[0m     \u001b[38;5;28;01mdel\u001b[39;00m filtered_tb\n",
      "File \u001b[0;32m~/anaconda3/lib/python3.9/site-packages/tensorflow/python/eager/execute.py:53\u001b[0m, in \u001b[0;36mquick_execute\u001b[0;34m(op_name, num_outputs, inputs, attrs, ctx, name)\u001b[0m\n\u001b[1;32m     51\u001b[0m \u001b[38;5;28;01mtry\u001b[39;00m:\n\u001b[1;32m     52\u001b[0m   ctx\u001b[38;5;241m.\u001b[39mensure_initialized()\n\u001b[0;32m---> 53\u001b[0m   tensors \u001b[38;5;241m=\u001b[39m pywrap_tfe\u001b[38;5;241m.\u001b[39mTFE_Py_Execute(ctx\u001b[38;5;241m.\u001b[39m_handle, device_name, op_name,\n\u001b[1;32m     54\u001b[0m                                       inputs, attrs, num_outputs)\n\u001b[1;32m     55\u001b[0m \u001b[38;5;28;01mexcept\u001b[39;00m core\u001b[38;5;241m.\u001b[39m_NotOkStatusException \u001b[38;5;28;01mas\u001b[39;00m e:\n\u001b[1;32m     56\u001b[0m   \u001b[38;5;28;01mif\u001b[39;00m name \u001b[38;5;129;01mis\u001b[39;00m \u001b[38;5;129;01mnot\u001b[39;00m \u001b[38;5;28;01mNone\u001b[39;00m:\n",
      "\u001b[0;31mInvalidArgumentError\u001b[0m: Graph execution error:\n\nDetected at node categorical_crossentropy/softmax_cross_entropy_with_logits defined at (most recent call last):\n  File \"/home/mattmori/anaconda3/lib/python3.9/runpy.py\", line 197, in _run_module_as_main\n\n  File \"/home/mattmori/anaconda3/lib/python3.9/runpy.py\", line 87, in _run_code\n\n  File \"/home/mattmori/anaconda3/lib/python3.9/site-packages/ipykernel_launcher.py\", line 16, in <module>\n\n  File \"/home/mattmori/anaconda3/lib/python3.9/site-packages/traitlets/config/application.py\", line 846, in launch_instance\n\n  File \"/home/mattmori/anaconda3/lib/python3.9/site-packages/ipykernel/kernelapp.py\", line 677, in start\n\n  File \"/home/mattmori/anaconda3/lib/python3.9/site-packages/tornado/platform/asyncio.py\", line 199, in start\n\n  File \"/home/mattmori/anaconda3/lib/python3.9/asyncio/base_events.py\", line 601, in run_forever\n\n  File \"/home/mattmori/anaconda3/lib/python3.9/asyncio/base_events.py\", line 1905, in _run_once\n\n  File \"/home/mattmori/anaconda3/lib/python3.9/asyncio/events.py\", line 80, in _run\n\n  File \"/home/mattmori/anaconda3/lib/python3.9/site-packages/ipykernel/kernelbase.py\", line 471, in dispatch_queue\n\n  File \"/home/mattmori/anaconda3/lib/python3.9/site-packages/ipykernel/kernelbase.py\", line 460, in process_one\n\n  File \"/home/mattmori/anaconda3/lib/python3.9/site-packages/ipykernel/kernelbase.py\", line 367, in dispatch_shell\n\n  File \"/home/mattmori/anaconda3/lib/python3.9/site-packages/ipykernel/kernelbase.py\", line 662, in execute_request\n\n  File \"/home/mattmori/anaconda3/lib/python3.9/site-packages/ipykernel/ipkernel.py\", line 360, in do_execute\n\n  File \"/home/mattmori/anaconda3/lib/python3.9/site-packages/ipykernel/zmqshell.py\", line 532, in run_cell\n\n  File \"/home/mattmori/anaconda3/lib/python3.9/site-packages/IPython/core/interactiveshell.py\", line 2863, in run_cell\n\n  File \"/home/mattmori/anaconda3/lib/python3.9/site-packages/IPython/core/interactiveshell.py\", line 2909, in _run_cell\n\n  File \"/home/mattmori/anaconda3/lib/python3.9/site-packages/IPython/core/async_helpers.py\", line 129, in _pseudo_sync_runner\n\n  File \"/home/mattmori/anaconda3/lib/python3.9/site-packages/IPython/core/interactiveshell.py\", line 3106, in run_cell_async\n\n  File \"/home/mattmori/anaconda3/lib/python3.9/site-packages/IPython/core/interactiveshell.py\", line 3309, in run_ast_nodes\n\n  File \"/home/mattmori/anaconda3/lib/python3.9/site-packages/IPython/core/interactiveshell.py\", line 3369, in run_code\n\n  File \"/tmp/ipykernel_14199/1985418639.py\", line 21, in <cell line: 21>\n\n  File \"/home/mattmori/anaconda3/lib/python3.9/site-packages/keras/src/utils/traceback_utils.py\", line 65, in error_handler\n\n  File \"/home/mattmori/anaconda3/lib/python3.9/site-packages/keras/src/engine/training.py\", line 1807, in fit\n\n  File \"/home/mattmori/anaconda3/lib/python3.9/site-packages/keras/src/engine/training.py\", line 1401, in train_function\n\n  File \"/home/mattmori/anaconda3/lib/python3.9/site-packages/keras/src/engine/training.py\", line 1384, in step_function\n\n  File \"/home/mattmori/anaconda3/lib/python3.9/site-packages/keras/src/engine/training.py\", line 1373, in run_step\n\n  File \"/home/mattmori/anaconda3/lib/python3.9/site-packages/keras/src/engine/training.py\", line 1151, in train_step\n\n  File \"/home/mattmori/anaconda3/lib/python3.9/site-packages/keras/src/engine/training.py\", line 1209, in compute_loss\n\n  File \"/home/mattmori/anaconda3/lib/python3.9/site-packages/keras/src/engine/compile_utils.py\", line 277, in __call__\n\n  File \"/home/mattmori/anaconda3/lib/python3.9/site-packages/keras/src/losses.py\", line 143, in __call__\n\n  File \"/home/mattmori/anaconda3/lib/python3.9/site-packages/keras/src/losses.py\", line 270, in call\n\n  File \"/home/mattmori/anaconda3/lib/python3.9/site-packages/keras/src/losses.py\", line 2221, in categorical_crossentropy\n\n  File \"/home/mattmori/anaconda3/lib/python3.9/site-packages/keras/src/backend.py\", line 5579, in categorical_crossentropy\n\nlogits and labels must be broadcastable: logits_size=[64,3] labels_size=[64,5]\n\t [[{{node categorical_crossentropy/softmax_cross_entropy_with_logits}}]] [Op:__inference_train_function_2741]"
     ]
    }
   ],
   "source": [
    "from keras.utils import np_utils\n",
    "from keras.models import Sequential\n",
    "from keras.layers import Dense, Conv2D, MaxPooling2D, Flatten, Dropout\n",
    "from IPython.display import display, Image\n",
    "from keras.layers import BatchNormalization\n",
    "from keras.callbacks import EarlyStopping\n",
    "import tensorflow as tf\n",
    "l2 = tf.keras.regularizers.l2(1e-4)\n",
    "\n",
    "model = Sequential()\n",
    "model.add(Conv2D(256, kernel_size=(3,3), activation='relu',input_shape=(256,256,3)))\n",
    "model.add(MaxPooling2D(2,2))\n",
    "model.add(Conv2D(64, kernel_size=(5,5), activation='relu'))\n",
    "model.add(MaxPooling2D(2,2))\n",
    "model.add(Flatten())\n",
    "model.add(Dense(16))\n",
    "model.add(Dense(3, activation='softmax'))\n",
    "            \n",
    "model.compile(loss='categorical_crossentropy',\n",
    "              optimizer='adam',metrics=['accuracy'])\n",
    "model.fit(train_generator,\n",
    "          steps_per_epoch=40,\n",
    "          epochs=50,\n",
    "          validation_data=(validation_generator),\n",
    "          validation_steps=10)\n",
    "\n"
   ]
  }
 ],
 "metadata": {
  "kernelspec": {
   "display_name": "Python 3 (ipykernel)",
   "language": "python",
   "name": "python3"
  },
  "language_info": {
   "codemirror_mode": {
    "name": "ipython",
    "version": 3
   },
   "file_extension": ".py",
   "mimetype": "text/x-python",
   "name": "python",
   "nbconvert_exporter": "python",
   "pygments_lexer": "ipython3",
   "version": "3.9.12"
  }
 },
 "nbformat": 4,
 "nbformat_minor": 5
}
